Workbook

Sheet Lookup_Tables
A1: LOOKUP TABLES
A3: A.1 Customer Size Bands — by Licensed User Count
A4: Band Name | B4: Min. Licensed Users | C4: Max. Licensed Users
A5: Small | B5: 0 | C5: 499
A6: Mid | B6: 500 | C6: 2499
A7: Enterprise | B7: 2500 | C7: 9999
A8: Strategic | B8: 10000 | C8: No limit
A10: Boundary Review Threshold | B10: 0.05
A12: A.2 Core Platform Base Price ($) — by Tier & Size Band
A13: Tier | B13: Small | C13: Mid | D13: Enterprise | E13: Strategic
A14: Data Security Essentials | B14: 14000 | C14: 32000 | D14: 68000 | E14: 130000
A15: Data Security Advanced | B15: 20000 | C15: 48000 | D15: 100000 | E15: 190000
A17: [ASSUMPTION] Core Platform prices are illustrative, anchored so Mid/Advanced + Cloud premium (~$57.6K) aligns with Varonis' publicly reported average contract value of ~$58K.
A19: A.3 Add-On Uplift % (applied to Core Platform Base Price)
A20: Add-On | B20: Uplift %
A21: MDDR (Managed Detection & Response) | B21: 0.25
A22: Identity Resolution | B22: 0.08
A23: Identity Posture | B23: 0.08
A24: AI Security (Atlas) | B24: 0.1
A26: [ASSUMPTION] MDDR, Identity Security, and AI Security (Atlas) price as a % uplift on Core Platform base — they extend the platform rather than standing alone. Identity Resolution and Identity Posture are modeled separately (rather than one combined 'Identity Security' line) to match Varonis' own site navigation, which lists them as distinct capabilities.
A28: A.4 Additional Modules ($) — Standalone, by Size Band
A29: Module | B29: Small | C29: Mid | D29: Enterprise | E29: Strategic
A30: Database Activity Monitoring | B30: 5000 | C30: 11000 | D30: 22000 | E30: 40000
A31: Data-Centric UEBA | B31: 6000 | C31: 13000 | D31: 26000 | E31: 46000
A32: DLP (Data Loss Prevention) | B32: 5500 | C32: 12000 | D32: 24000 | E32: 42000
A33: ITDR | B33: 6500 | C33: 14000 | D33: 28000 | E33: 50000
A34: Interceptor Email Security | B34: 2500 | C34: 5500 | D34: 11000 | E34: 19000
A35: Interceptor Browser Security | B35: 1500 | C35: 3500 | D35: 7000 | E35: 12000
A36: Email Data Protection | B36: 3000 | C36: 7000 | D36: 14000 | E36: 25000
A38: [ASSUMPTION] These are modeled as standalone selectable modules (flat price by band), reflecting the Varonis platform's individually-listed capabilities. Interceptor is split into Email Security and Browser Security (separate nav items on varonis.com) rather than one combined product, and Email Data Protection is modeled as a distinct module from Interceptor Email Security (real-time threat detection vs. data-loss-prevention/classification for email content).
A40: [SCOPE NOTE] Varonis' site also lists 'Solutions' (Insider Risk Management, Ransomware Prevention, Compliance Management, Cloud Data Security, Data Lifecycle Automation, Dev Cycle Data Security) and industry/vertical pages (Finance, Healthcare, Manufacturing, SLED, US Federal). These are use-case bundles and marketing pages built from the modules already priced above, not separately billable line items — pricing them again here would double-count revenue.
A42: A.5 Deployment & Contract Term Adjustments
A43: Adjustment | B43: Factor
A44: Cloud Deployment Multiplier | B44: 1.2
A45: On-Prem Deployment Multiplier | B45: 1
A46: 1-Year Term Factor | B46: 1
A47: 2-Year Term Factor | B47: 0.97
A48: 3-Year Term Factor | B48: 0.95
A50: [ASSUMPTION] Cloud premium (+20%) and multi-year term discounts (-3%/-5%) reflect common enterprise SaaS practice; not disclosed Varonis figures.
A52: A.6 Implementation Fee ($, One-Time) — T-Shirt Sized, Per Component
...

Sheet Deal_Log
A1: DEAL LOG — Historical Quotes (for reporting / Power BI)
A2: Synthetic illustrative deals for demonstration. In real use, copy each completed quote's key figures here (paste as values) after Approval Workflow reaches 'Approved'.
A4: Deal ID | B4: Deal Name | C4: Account Manager | D4: Team / Market Segment | E4: Deal Type | F4: Quote Date | G4: Licensed Users | H4: Band | I4: Deployment | J4: Term | K4: Platform Tier | L4: Industry | M4: Currency | N4: List ACV (USD) | O4: Discount % | P4: Net ACV (USD) | Q4: PUPY (USD) | R4: Implementation Fee (USD) | S4: TCV (USD) | T4: Shrinkage Flag | U4: Migration Flag | V4: Approval Status
A5: D-1000 | B5: Acme Financial Corp | C5: Rahul Rao | D5: Enterprise — BFSI & Healthcare | E5: Renewal | F5: 2026-01-01 | G5: 162 | H5: Small | I5: Cloud | J5: 1yr | K5: Data Security Essentials | L5: Healthcare | M5: USD | N5: =INDEX(Lookup_Tables!$B$14:$E$15,MATCH(K5,Lookup_Tables!$A$14:$A$15,0),MATCH(H5,Lookup_Tables!$B$13:$E$13,0))*IF(I5="Cloud",Lookup_Tables!$B$44,Lookup_Tables!$B$45)*IF(J5="1yr",Lookup_Tables!$B$46,IF(J5="2yr",Lookup_Tables!$B$47,Lookup_Tables!$B$48)) -> 16800 | O5: 0.222 | P5: =N5*(1-O5) -> 13070.4 | Q5: =P5/G5 -> 80.681481 | R5: =INDEX(Lookup_Tables!$B$54:$E$66,MATCH(IF(I5="Cloud","Core Platform — Cloud","Core Platform — On-Prem"),Lookup_Tables!$A$54:$A$66,0),MATCH(H5,Lookup_Tables!$B$13:$E$13,0)) -> 8000 | S5: =P5*VALUE(LEFT(J5,1))+R5 -> 21070.4 | T5: Renewal Shrinkage — Escalate | U5: Deployment Migration — Escalate | V5: Needs Review
A6: D-1001 | B6: Bluewave Health Systems | C6: Arjun Verma | D6: Mid-Market — General / SMB | E6: New Business | F6: 2026-02-04 | G6: 197 | H6: Small | I6: On-Prem | J6: 1yr | K6: Data Security Essentials | L6: Manufacturing / Industrial | M6: USD | N6: =INDEX(Lookup_Tables!$B$14:$E$15,MATCH(K6,Lookup_Tables!$A$14:$A$15,0),MATCH(H6,Lookup_Tables!$B$13:$E$13,0))*IF(I6="Cloud",Lookup_Tables!$B$44,Lookup_Tables!$B$45)*IF(J6="1yr",Lookup_Tables!$B$46,IF(J6="2yr",Lookup_Tables!$B$47,Lookup_Tables!$B$48)) -> 14000 | O6: 0.195 | P6: =N6*(1-O6) -> 11270 | Q6: =P6/G6 -> 57.208122 | R6: =INDEX(Lookup_Tables!$B$54:$E$66,MATCH(IF(I6="Cloud","Core Platform — Cloud","Core Platform — On-Prem"),Lookup_Tables!$A$54:$A$66,0),MATCH(H6,Lookup_Tables!$B$13:$E$13,0)) -> 12000 | S6: =P6*VALUE(LEFT(J6,1))+R6 -> 23270 | T6: OK | U6: OK | V6: Needs Review
A7: D-1002 | B7: Cascade Manufacturing | C7: Divya Mehta | D7: Enterprise — BFSI & Healthcare | E7: New Business | F7: 2026-03-07 | G7: 2753 | H7: Enterprise | I7: On-Prem | J7: 3yr | K7: Data Security Advanced | L7: Public Sector / Government | M7: USD | N7: =INDEX(Lookup_Tables!$B$14:$E$15,MATCH(K7,Lookup_Tables!$A$14:$A$15,0),MATCH(H7,Lookup_Tables!$B$13:$E$13,0))*IF(I7="Cloud",Lookup_Tables!$B$44,Lookup_Tables!$B$45)*IF(J7="1yr",Lookup_Tables!$B$46,IF(J7="2yr",Lookup_Tables!$B$47,Lookup_Tables!$B$48)) -> 95000 | O7: 0.065 | P7: =N7*(1-O7) -> 88825 | Q7: =P7/G7 -> 32.264802 | R7: =INDEX(Lookup_Tables!$B$54:$E$66,MATCH(IF(I7="Cloud","Core Platform — Cloud","Core Platform — On-Prem"),Lookup_Tables!$A$54:$A$66,0),MATCH(H7,Lookup_Tables!$B$13:$E$13,0)) -> 50000 | S7: =P7*VALUE(LEFT(J7,1))+R7 -> 316475 | T7: OK | U7: OK | V7: Approved
A8: D-1003 | B8: Delta Public Services | C8: Arjun Mehta | D8: Strategic Accounts (Global) | E8: New Business | F8: 2026-04-10 | G8: 12084 | H8: Strategic | I8: Cloud | J8: 2yr | K8: Data Security Advanced | L8: BFSI (Banking, Financial Services, Insurance) | M8: GBP | N8: =INDEX(Lookup_Tables!$B$14:$E$15,MATCH(K8,Lookup_Tables!$A$14:$A$15,0),MATCH(H8,Lookup_Tables!$B$13:$E$13,0))*IF(I8="Cloud",Lookup_Tables!$B$44,Lookup_Tables!$B$45)*IF(J8="1yr",Lookup_Tables!$B$46,IF(J8="2yr",Lookup_Tables!$B$47,Lookup_Tables!$B$48)) -> 221160 | O8: 0.037 | P8: =N8*(1-O8) -> 212977.08 | Q8: =P8/G8 -> 17.624717 | R8: =INDEX(Lookup_Tables!$B$54:$E$66,MATCH(IF(I8="Cloud","Core Platform — Cloud","Core Platform — On-Prem"),Lookup_Tables!$A$54:$A$66,0),MATCH(H8,Lookup_Tables!$B$13:$E$13,0)) -> 50000 | S8: =P8*VALUE(LEFT(J8,1))+R8 -> 475954.16 | T8: OK | U8: OK | V8: Needs Review
A9: D-1004 | B9: Everline Technologies | C9: Sara Mehta | D9: Enterprise — Public Sector & Manufacturing | E9: New Business | F9: 2026-05-13 | G9: 7849 | H9: Enterprise | I9: Cloud | J9: 3yr | K9: Data Security Essentials | L9: Other | M9: USD | N9: =INDEX(Lookup_Tables!$B$14:$E$15,MATCH(K9,Lookup_Tables!$A$14:$A$15,0),MATCH(H9,Lookup_Tables!$B$13:$E$13,0))*IF(I9="Cloud",Lookup_Tables!$B$44,Lookup_Tables!$B$45)*IF(J9="1yr",Lookup_Tables!$B$46,IF(J9="2yr",Lookup_Tables!$B$47,Lookup_Tables!$B$48)) -> 77520 | O9: 0.198 | P9: =N9*(1-O9) -> 62171.04 | Q9: =P9/G9 -> 7.9208867 | R9: =INDEX(Lookup_Tables!$B$54:$E$66,MATCH(IF(I9="Cloud","Core Platform — Cloud","Core Platform — On-Prem"),Lookup_Tables!$A$54:$A$66,0),MATCH(H9,Lookup_Tables!$B$13:$E$13,0)) -> 30000 | S9: =P9*VALUE(LEFT(J9,1))+R9 -> 216513.12 | T9: OK | U9: OK | V9: Approved
A10: D-1005 | B10: Fortress Insurance Group | C10: Sara Mehta | D10: Strategic Accounts (Global) | E10: Renewal | F10: 2026-06-16 | G10: 344 | H10: Small | I10: Cloud | J10: 2yr | K10: Data Security Advanced | L10: Healthcare | M10: USD | N10: =INDEX(Lookup_Tables!$B$14:$E$15,MATCH(K10,Lookup_Tables!$A$14:$A$15,0),MATCH(H10,Lookup_Tables!$B$13:$E$13,0))*IF(I10="Cloud",Lookup_Tables!$B$44,Lookup_Tables!$B$45)*IF(J10="1yr",Lookup_Tables!$B$46,IF(J10="2yr",Lookup_Tables!$B$47,Lookup_Tables!$B$48)) -> 23280 | O10: 0.063 | P10: =N10*(1-O10) -> 21813.36 | Q10: =P10/G10 -> 63.41093 | R10: =INDEX(Lookup_Tables!$B$54:$E$66,MATCH(IF(I10="Cloud","Core Platform — Cloud","Core Platform — On-Prem"),Lookup_Tables!$A$54:$A$66,0),MATCH(H10,Lookup_Tables!$B$13:$E$13,0)) -> 8000 | S10: =P10*VALUE(LEFT(J10,1))+R10 -> 51626.72 | T10: OK | U10: OK | V10: Approved
A11: D-1006 | B11: Granite Bank & Trust | C11: Karan Nair | D11: Enterprise — BFSI & Healthcare | E11: New Business | F11: 2026-07-19 | G11: 1693 | H11: Mid | I11: On-Prem | J11: 1yr | K11: Data Security Advanced | L11: Technology / SaaS | M11: USD | N11: =INDEX(Lookup_Tables!$B$14:$E$15,MATCH(K11,Lookup_Tables!$A$14:$A$15,0),MATCH(H11,Lookup_Tables!$B$13:$E$13,0))*IF(I11="Cloud",Lookup_Tables!$B$44,Lookup_Tables!$B$45)*IF(J11="1yr",Lookup_Tables!$B$46,IF(J11="2yr",Lookup_Tables!$B$47,Lookup_Tables!$B$48)) -> 48000 | O11: 0.206 | P11: =N11*(1-O11) -> 38112 | Q11: =P11/G11 -> 22.511518 | R11: =INDEX(Lookup_Tables!$B$54:$E$66,MATCH(IF(I11="Cloud","Core Platform — Cloud","Core Platform — On-Prem"),Lookup_Tables!$A$54:$A$66,0),MATCH(H11,Lookup_Tables!$B$13:$E$13,0)) -> 25000 | S11: =P11*VALUE(LEFT(J11,1))+R11 -> 63112 | T11: OK | U11: OK | V11: Needs Review
A12: D-1007 | B12: Harbor Logistics | C12: Divya Verma | D12: Commercial — Emerging Accounts | E12: New Business | F12: 2026-01-22 | G12: 2283 | H12: Mid | I12: On-Prem | J12: 2yr | K12: Data Security Advanced | L12: Public Sector / Government | M12: USD | N12: =INDEX(Lookup_Tables!$B$14:$E$15,MATCH(K12,Lookup_Tables!$A$14:$A$15,0),MATCH(H12,Lookup_Tables!$B$13:$E$13,0))*IF(I12="Cloud",Lookup_Tables!$B$44,Lookup_Tables!$B$45)*IF(J12="1yr",Lookup_Tables!$B$46,IF(J12="2yr",Lookup_Tables!$B$47,Lookup_Tables!$B$48)) -> 46560 | O12: 0.274 | P12: =N12*(1-O12) -> 33802.56 | Q12: =P12/G12 -> 14.806202 | R12: =INDEX(Lookup_Tables!$B$54:$E$66,MATCH(IF(I12="Cloud","Core Platform — Cloud","Core Platform — On-Prem"),Lookup_Tables!$A$54:$A$66,0),MATCH(H12,Lookup_Tables!$B$13:$E$13,0)) -> 25000 | S12: =P12*VALUE(LEFT(J12,1))+R12 -> 92605.12 | T12: OK | U12: OK | V12: Approved
A13: D-1008 | B13: Ironclad Pharma | C13: Sara Rao | D13: Strategic Accounts (Global) | E13: New Business | F13: 2026-02-25 | G13: 16982 | H13: Strategic | I13: Cloud | J13: 1yr | K13: Data Security Advanced | L13: Healthcare | M13: USD | N13: =INDEX(Lookup_Tables!$B$14:$E$15,MATCH(K13,Lookup_Tables!$A$14:$A$15,0),MATCH(H13,Lookup_Tables!$B$13:$E$13,0))*IF(I13="Cloud",Lookup_Tables!$B$44,Lookup_Tables!$B$45)*IF(J13="1yr",Lookup_Tables!$B$46,IF(J13="2yr",Lookup_Tables!$B$47,Lookup_Tables!$B$48)) -> 228000 | O13: 0.168 | P13: =N13*(1-O13) -> 189696 | Q13: =P13/G13 -> 11.170416 | R13: =INDEX(Lookup_Tables!$B$54:$E$66,MATCH(IF(I13="Cloud","Core Platform — Cloud","Core Platform — On-Prem"),Lookup_Tables!$A$54:$A$66,0),MATCH(H13,Lookup_Tables!$B$13:$E$13,0)) -> 50000 | S13: =P13*VALUE(LEFT(J13,1))+R13 -> 239696 | T13: OK | U13: OK | V13: Needs Review
A14: D-1009 | B14: Juniper SaaS Co | C14: Ananya Rao | D14: Strategic Accounts (Global) | E14: New Business | F14: 2026-03-01 | G14: 16430 | H14: Strategic | I14: On-Prem | J14: 1yr | K14: Data Security Advanced | L14: BFSI (Banking, Financial Services, Insurance) | M14: USD | N14: =INDEX(Lookup_Tables!$B$14:$E$15,MATCH(K14,Lookup_Tables!$A$14:$A$15,0),MATCH(H14,Lookup_Tables!$B$13:$E$13,0))*IF(I14="Cloud",Lookup_Tables!$B$44,Lookup_Tables!$B$45)*IF(J14="1yr",Lookup_Tables!$B$46,IF(J14="2yr",Lookup_Tables!$B$47,Lookup_Tables!$B$48)) -> 190000 | O14: 0.046 | P14: =N14*(1-O14) -> 181260 | Q14: =P14/G14 -> 11.032258 | R14: =INDEX(Lookup_Tables!$B$54:$E$66,MATCH(IF(I14="Cloud","Core Platform — Cloud","Core Platform — On-Prem"),Lookup_Tables!$A$54:$A$66,0),MATCH(H14,Lookup_Tables!$B$13:$E$13,0)) -> 85000 | S14: =P14*VALUE(LEFT(J14,1))+R14 -> 266260 | T14: OK | U14: OK | V14: Approved
A15: D-1010 | B15: Kestrel Energy | C15: Priya Mehta | D15: Commercial — Emerging Accounts | E15: Renewal | F15: 2026-04-04 | G15: 347 | H15: Small | I15: Cloud | J15: 3yr | K15: Data Security Advanced | L15: Manufacturing / Industrial | M15: USD | N15: =INDEX(Lookup_Tables!$B$14:$E$15,MATCH(K15,Lookup_Tables!$A$14:$A$15,0),MATCH(H15,Lookup_Tables!$B$13:$E$13,0))*IF(I15="Cloud",Lookup_Tables!$B$44,Lookup_Tables!$B$45)*IF(J15="1yr",Lookup_Tables!$B$46,IF(J15="2yr",Lookup_Tables!$B$47,Lookup_Tables!$B$48)) -> 22800 | O15: 0.258 | P15: =N15*(1-O15) -> 16917.6 | Q15: =P15/G15 -> 48.75389 | R15: =INDEX(Lookup_Tables!$B$54:$E$66,MATCH(IF(I15="Cloud","Core Platform — Cloud","Core Platform — On-Prem"),Lookup_Tables!$A$54:$A$66,0),MATCH(H15,Lookup_Tables!$B$13:$E$13,0)) -> 8000 | S15: =P15*VALUE(LEFT(J15,1))+R15 -> 58752.8 | T15: Renewal Shrinkage — Escalate | U15: OK | V15: Needs Review
A16: D-1011 | B16: Lumina Retail Group | C16: Sara Iyer | D16: Strategic Accounts (Global) | E16: New Business | F16: 2026-05-07 | G16: 8996 | H16: Enterprise | I16: Cloud | J16: 1yr | K16: Data Security Advanced | L16: Technology / SaaS | M16: USD | N16: =INDEX(Lookup_Tables!$B$14:$E$15,MATCH(K16,Lookup_Tables!$A$14:$A$15,0),MATCH(H16,Lookup_Tables!$B$13:$E$13,0))*IF(I16="Cloud",Lookup_Tables!$B$44,Lookup_Tables!$B$45)*IF(J16="1yr",Lookup_Tables!$B$46,IF(J16="2yr",Lookup_Tables!$B$47,Lookup_Tables!$B$48)) -> 120000 | O16: 0.001 | P16: =N16*(1-O16) -> 119880 | Q16: =P16/G16 -> 13.325923 | R16: =INDEX(Lookup_Tables!$B$54:$E$66,MATCH(IF(I16="Cloud","Core Platform — Cloud","Core Platform — On-Prem"),Lookup_Tables!$A$54:$A$66,0),MATCH(H16,Lookup_Tables!$B$13:$E$13,0)) -> 30000 | S16: =P16*VALUE(LEFT(J16,1))+R16 -> 149880 | T16: OK | U16: OK | V16: Approved
... A22: D-1017 | B22: Redstone Financial | C22: Rahul Rao | D22: Mid-Market — Technology | E22: New Business | F22: 2026-04-25 | G22: 14010 | H22: Strategic | I22: On-Prem | J22: 3yr | K22: Data Security Advanced | L22: Healthcare | M22: GBP | N22: =INDEX(Lookup_Tables!$B$14:$E$15,MATCH(K22,Lookup_Tables!$A$14:$A$15,0),MATCH(H22,Lookup_Tables!$B$13:$E$13,0))*IF(I22="Cloud",Lookup_Tables!$B$44,Lookup_Tables!$B$45)*IF(J22="1yr",Lookup_Tables!$B$46,IF(J22="2yr",Lookup_Tables!$B$47,Lookup_Tables!$B$48)) -> 180500 | O22: 0.057 | P22: =N22*(1-O22) -> 170211.5 | Q22: =P22/G22 -> 12.149286 | R22: =INDEX(Lookup_Tables!$B$54:$E$66,MATCH(IF(I22="Cloud","Core Platform — Cloud","Core Platform — On-Prem"),Lookup_Tables!$A$54:$A$66,0),MATCH(H22,Lookup_Tables!$B$13:$E$13,0)) -> 85000 | S22: =P22*VALUE(LEFT(J22,1))+R22 -> 595634.5 | T22: OK | U22: OK | V22: Approved
A24: [ASSUMPTION] Account Manager names, team assignments, dates, and flags are randomly generated for demonstration. List ACV/PUPY/Implementation/TCV are computed live via the same Lookup_Tables pricing engine as Pricing_Calculation — change any Lookup_Tables price and every row here recalculates too. Discount %, deal type, and flags are illustrative fixed values, not formula-driven.

Sheet Deal_Input
A1: DEAL INPUT — New Business (blue cells = editable)
A3: Deal Sizing
A4: Deal Name | B4: Acme Financial Corp
A5: Licensed User Count | B5: 1800
A6: Number of Data Sources / Repositories | B6: 12
A7: Assigned Size Band (auto) | B7: =IF(B5>=Lookup_Tables!$B$8,"Strategic",IF(B5>=Lookup_Tables!$B$7,"Enterprise",IF(B5>=Lookup_Tables!$B$6,"Mid","Small"))) -> Mid
A8: Boundary Review Flag (auto) | B8: =IF(MIN(ABS(B5-Lookup_Tables!$B$6)/Lookup_Tables!$B$6,ABS(B5-Lookup_Tables!$B$7)/Lookup_Tables!$B$7,ABS(B5-Lookup_Tables!$B$8)/Lookup_Tables!$B$8)<=Lookup_Tables!$B$10,"Review Band Assignment","OK") -> OK
A10: Deal Terms
A11: Deployment Type | B11: Cloud
A12: Contract Term | B12: 2yr
A13: Platform Tier | B13: Data Security Advanced
A14: Industry | B14: BFSI (Banking, Financial Services, Insurance)
A15: Recommended Add-Ons (auto, informational only) | B15: =INDEX(Lookup_Tables!$B$76:$B$81,MATCH(B14,Lookup_Tables!$A$76:$A$81,0)) -> Identity Security, MDDR
A17: Add-Ons Selected (Yes/No)
A18: MDDR (Managed Detection & Response) | B18: Yes
A19: Identity Resolution | B19: Yes
A20: Identity Posture | B20: No
A21: AI Security (Atlas) | B21: No
A23: Additional Modules Selected (Yes/No)
A24: Database Activity Monitoring | B24: No
A25: Data-Centric UEBA | B25: Yes
A26: DLP (Data Loss Prevention) | B26: No
A27: ITDR | B27: No
A28: Interceptor Email Security | B28: Yes
A29: Interceptor Browser Security | B29: No
A30: Email Data Protection | B30: No
A32: Legend: Blue cells = editable inputs. Black cells = automatic formulas — do not overwrite. Concierge and Athena AI are always included and are not entered here.
A34: Account Manager
A35: Account Manager Name (free text) | B35: Priya Sharma
A36: Team / Market Segment (free text) | B36: Enterprise — BFSI & Healthcare

Sheet Deal_Overview
A1: DEAL OVERVIEW — New Business (Account Manager View)
A3: Currency | B3: USD
A5: Deal Snapshot
A6: Deal Name | B6: =Deal_Input!B4 -> Acme Financial Corp
A7: Account Manager Name | B7: =Deal_Input!B35 -> Priya Sharma
A8: Team / Market Segment | B8: =Deal_Input!B36 -> Enterprise — BFSI & Healthcare
A9: Licensed Users | B9: =Deal_Input!B5 -> 1800
A10: Assigned Size Band | B10: =Deal_Input!B7 -> Mid
A11: Deployment Type | B11: =Deal_Input!B11 -> Cloud
A12: Contract Term | B12: =Deal_Input!B12 -> 2yr
A13: Platform Tier | B13: =Deal_Input!B13 -> Data Security Advanced
A14: Industry | B14: =Deal_Input!B14 -> BFSI (Banking, Financial Services, Insurance)
A16: RECURRING (ARR)
A17: Line Item | B17: Amount
A18: Core Platform | B18: =(NB_Pricing_Calculation!$B$6)*NB_Pricing_Calculation!$B$57 -> 48000
A19: MDDR (Managed Detection & Response) | B19: =(NB_Pricing_Calculation!$D$10)*NB_Pricing_Calculation!$B$57 -> 12000
A20: Identity Resolution | B20: =(NB_Pricing_Calculation!$D$11)*NB_Pricing_Calculation!$B$57 -> 3840
A21: Identity Posture | B21: =(NB_Pricing_Calculation!$D$12)*NB_Pricing_Calculation!$B$57 -> 0
A22: AI Security (Atlas) | B22: =(NB_Pricing_Calculation!$D$13)*NB_Pricing_Calculation!$B$57 -> 0
A23: Database Activity Monitoring | B23: =(NB_Pricing_Calculation!$D$17)*NB_Pricing_Calculation!$B$57 -> 0
A24: Data-Centric UEBA | B24: =(NB_Pricing_Calculation!$D$18)*NB_Pricing_Calculation!$B$57 -> 13000
A25: DLP (Data Loss Prevention) | B25: =(NB_Pricing_Calculation!$D$19)*NB_Pricing_Calculation!$B$57 -> 0
A26: ITDR | B26: =(NB_Pricing_Calculation!$D$20)*NB_Pricing_Calculation!$B$57 -> 0
A27: Interceptor Email Security | B27: =(NB_Pricing_Calculation!$D$21)*NB_Pricing_Calculation!$B$57 -> 5500
A28: Interceptor Browser Security | B28: =(NB_Pricing_Calculation!$D$22)*NB_Pricing_Calculation!$B$57 -> 0
A29: Email Data Protection | B29: =(NB_Pricing_Calculation!$D$23)*NB_Pricing_Calculation!$B$57 -> 0
A30: Varonis Concierge | B30: Included
A31: Athena AI | B31: Included
A33: List ACV (Year 1) | B33: =NB_Pricing_Calculation!$B$59 -> 95843.76
A34: Discount % (live input) | B34: 0
A35: Net ACV | B35: =B33*(1-B34) -> 95843.76
A36: PUPY (Per User Per Year) | B36: =B35/Deal_Input!$B$5 -> 53.246533
A37: PUPM (Per User Per Month) | B37: =B36/12 -> 4.4372111
A39: ONE-TIME (Implementation)
A40: Core Platform | B40: =(NB_Pricing_Calculation!$B$35)*NB_Pricing_Calculation!$B$57 -> 15000
A41: MDDR (Managed Detection & Response) | B41: =(NB_Pricing_Calculation!$B$36)*NB_Pricing_Calculation!$B$57 -> 4000
A42: Identity Resolution | B42: =(NB_Pricing_Calculation!$B$37)*NB_Pricing_Calculation!$B$57 -> 1600
A43: Identity Posture | B43: =(NB_Pricing_Calculation!$B$38)*NB_Pricing_Calculation!$B$57 -> 0
A44: AI Security (Atlas) | B44: =(NB_Pricing_Calculation!$B$39)*NB_Pricing_Calculation!$B$57 -> 0
A45: Database Activity Monitoring | B45: =(NB_Pricing_Calculation!$B$40)*NB_Pricing_Calculation!$B$57 -> 0
...

Sheet NB_Pricing_Calculation
A1: PRICING CALCULATION — New Business Engine (Pricing Team Only — Hidden/Protected)
A3: Core Platform Pricing
A4: Selected Tier | B4: =Deal_Input!B13 -> Data Security Advanced
A5: Assigned Size Band | B5: =Deal_Input!B7 -> Mid
A6: Core Platform Base Price | B6: =INDEX(Lookup_Tables!$B$14:$E$15,MATCH(Deal_Input!$B$13,Lookup_Tables!$A$14:$A$15,0),MATCH($B$5,Lookup_Tables!$B$13:$E$13,0)) -> 48000
A8: Add-On Line Items (% uplift on Core Platform Base)
A9: Add-On | B9: Selected? | C9: Uplift % | D9: Amount
A10: MDDR (Managed Detection & Response) | B10: =Deal_Input!B18 -> Yes | C10: =Lookup_Tables!$B$21 -> 0.25 | D10: =IF(B10="Yes",$B$6*C10,0) -> 12000
A11: Identity Resolution | B11: =Deal_Input!B19 -> Yes | C11: =Lookup_Tables!$B$22 -> 0.08 | D11: =IF(B11="Yes",$B$6*C11,0) -> 3840
A12: Identity Posture | B12: =Deal_Input!B20 -> No | C12: =Lookup_Tables!$B$23 -> 0.08 | D12: =IF(B12="Yes",$B$6*C12,0) -> 0
A13: AI Security (Atlas) | B13: =Deal_Input!B21 -> No | C13: =Lookup_Tables!$B$24 -> 0.1 | D13: =IF(B13="Yes",$B$6*C13,0) -> 0
A15: Additional Modules Line Items (flat price by band)
A16: Module | B16: Selected? | C16: Unit Price | D16: Amount
A17: Database Activity Monitoring | B17: =Deal_Input!B24 -> No | C17: =INDEX(Lookup_Tables!$B$30:$E$30,MATCH($B$5,Lookup_Tables!$B$29:$E$29,0)) -> 11000 | D17: =IF(B17="Yes",C17,0) -> 0
A18: Data-Centric UEBA | B18: =Deal_Input!B25 -> Yes | C18: =INDEX(Lookup_Tables!$B$31:$E$31,MATCH($B$5,Lookup_Tables!$B$29:$E$29,0)) -> 13000 | D18: =IF(B18="Yes",C18,0) -> 13000
A19: DLP (Data Loss Prevention) | B19: =Deal_Input!B26 -> No | C19: =INDEX(Lookup_Tables!$B$32:$E$32,MATCH($B$5,Lookup_Tables!$B$29:$E$29,0)) -> 12000 | D19: =IF(B19="Yes",C19,0) -> 0
A20: ITDR | B20: =Deal_Input!B27 -> No | C20: =INDEX(Lookup_Tables!$B$33:$E$33,MATCH($B$5,Lookup_Tables!$B$29:$E$29,0)) -> 14000 | D20: =IF(B20="Yes",C20,0) -> 0
A21: Interceptor Email Security | B21: =Deal_Input!B28 -> Yes | C21: =INDEX(Lookup_Tables!$B$34:$E$34,MATCH($B$5,Lookup_Tables!$B$29:$E$29,0)) -> 5500 | D21: =IF(B21="Yes",C21,0) -> 5500
A22: Interceptor Browser Security | B22: =Deal_Input!B29 -> No | C22: =INDEX(Lookup_Tables!$B$35:$E$35,MATCH($B$5,Lookup_Tables!$B$29:$E$29,0)) -> 3500 | D22: =IF(B22="Yes",C22,0) -> 0
A23: Email Data Protection | B23: =Deal_Input!B30 -> No | C23: =INDEX(Lookup_Tables!$B$36:$E$36,MATCH($B$5,Lookup_Tables!$B$29:$E$29,0)) -> 7000 | D23: =IF(B23="Yes",C23,0) -> 0
A25: Platform Subtotal (Core + Add-Ons + Additional Modules) | D25: =$B$6+SUM(D10:D13)+SUM(D17:D23) -> 82340
A27: Deployment & Term Adjustment
A28: Cloud Multiplier Applied | B28: =IF(Deal_Input!$B$11="Cloud",Lookup_Tables!$B$44,Lookup_Tables!$B$45) -> 1.2
A29: Subtotal After Cloud Premium | B29: =D25*B28 -> 98808
A30: Term Adjustment Factor | B30: =IF(Deal_Input!$B$12="1yr",Lookup_Tables!$B$46,IF(Deal_Input!$B$12="2yr",Lookup_Tables!$B$47,IF(Deal_Input!$B$12="3yr",Lookup_Tables!$B$48,1))) -> 0.97
A31: TOTAL LIST ACV (Recurring, USD) | B31: =B29*B30 -> 95843.76
A33: Implementation Fee (One-Time, USD, Not Multiplied by Term)
A34: T-Shirt column matched using the same band position as Core Platform pricing.
A35: Core Platform Implementation | B35: =INDEX(Lookup_Tables!$B$54:$E$66,MATCH(IF(Deal_Input!$B$11="Cloud","Core Platform — Cloud","Core Platform — On-Prem"),Lookup_Tables!$A$54:$A$66,0),MATCH($B$5,Lookup_Tables!$B$13:$E$13,0)) -> 15000
A36: MDDR (Managed Detection & Response) Implementation | B36: =IF(Deal_Input!B18="Yes",INDEX(Lookup_Tables!$B$56:$E$56,MATCH($B$5,Lookup_Tables!$B$13:$E$13,0)),0) -> 4000
A37: Identity Resolution Implementation | B37: =IF(Deal_Input!B19="Yes",INDEX(Lookup_Tables!$B$57:$E$57,MATCH($B$5,Lookup_Tables!$B$13:$E$13,0)),0) -> 1600
A38: Identity Posture Implementation | B38: =IF(Deal_Input!B20="Yes",INDEX(Lookup_Tables!$B$58:$E$58,MATCH($B$5,Lookup_Tables!$B$13:$E$13,0)),0) -> 0
A39: AI Security (Atlas) Implementation | B39: =IF(Deal_Input!B21="Yes",INDEX(Lookup_Tables!$B$59:$E$59,MATCH($B$5,Lookup_Tables!$B$13:$E$13,0)),0) -> 0
A40: Database Activity Monitoring Implementation | B40: =IF(Deal_Input!B24="Yes",INDEX(Lookup_Tables!$B$60:$E$60,MATCH($B$5,Lookup_Tables!$B$13:$E$13,0)),0) -> 0
A41: Data-Centric UEBA Implementation | B41: =IF(Deal_Input!B25="Yes",INDEX(Lookup_Tables!$B$61:$E$61,MATCH($B$5,Lookup_Tables!$B$13:$E$13,0)),0) -> 3000
A42: DLP (Data Loss Prevention) Implementation | B42: =IF(Deal_Input!B26="Yes",INDEX(Lookup_Tables!$B$62:$E$62,MATCH($B$5,Lookup_Tables!$B$13:$E$13,0)),0) -> 0
A43: ITDR Implementation | B43: =IF(Deal_Input!B27="Yes",INDEX(Lookup_Tables!$B$63:$E$63,MATCH($B$5,Lookup_Tables!$B$13:$E$13,0)),0) -> 0
A44: Interceptor Email Security Implementation | B44: =IF(Deal_Input!B28="Yes",INDEX(Lookup_Tables!$B$64:$E$64,MATCH($B$5,Lookup_Tables!$B$13:$E$13,0)),0) -> 1800
A45: Interceptor Browser Security Implementation | B45: =IF(Deal_Input!B29="Yes",INDEX(Lookup_Tables!$B$65:$E$65,MATCH($B$5,Lookup_Tables!$B$13:$E$13,0)),0) -> 0
A46: Email Data Protection Implementation | B46: =IF(Deal_Input!B30="Yes",INDEX(Lookup_Tables!$B$66:$E$66,MATCH($B$5,Lookup_Tables!$B$13:$E$13,0)),0) -> 0
...

Sheet Renewal_Input
A1: RENEWAL INPUT — Existing Customer Parameters (blue cells)
A2: Existing Customer / Prior Contract
A3: Customer Name | B3: Acme Financial Corp
A4: Prior Contract Value (last term's Net ACV, USD) | B4: 88696.8
A5: Prior Platform Tier | B5: Data Security Advanced
A6: Prior Deployment Type | B6: On-Prem
A7: Licensed User Count (current) | B7: 1800
A8: Assigned Size Band (auto) | B8: =IF(B7>=Lookup_Tables!$B$8,"Strategic",IF(B7>=Lookup_Tables!$B$7,"Enterprise",IF(B7>=Lookup_Tables!$B$6,"Mid","Small"))) -> Mid
A9: Months to Renewal Date | B9: 3
A11: Prior Add-Ons / Additional Modules / Interceptor Status
A12: MDDR (Managed Detection & Response) (prior status) | B12: Yes
A13: Identity Resolution (prior status) | B13: No
A14: Identity Posture (prior status) | B14: No
A15: AI Security (Atlas) (prior status) | B15: No
A16: Database Activity Monitoring (prior status) | B16: No
A17: Data-Centric UEBA (prior status) | B17: No
A18: DLP (Data Loss Prevention) (prior status) | B18: No
A19: ITDR (prior status) | B19: No
A20: Interceptor Email Security (prior status) | B20: No
A21: Interceptor Browser Security (prior status) | B21: No
A22: Email Data Protection (prior status) | B22: No
A24: Renewal Requests
A25: Renewal Term | B25: 2yr
A26: MDDR (Managed Detection & Response) — Requested Action | B26: No Change
A27: Identity Resolution — Requested Action | B27: Add
A28: Identity Posture — Requested Action | B28: No Change
A29: AI Security (Atlas) — Requested Action | B29: No Change
A30: Database Activity Monitoring — Requested Action | B30: No Change
A31: Data-Centric UEBA — Requested Action | B31: No Change
A32: DLP (Data Loss Prevention) — Requested Action | B32: No Change
A33: ITDR — Requested Action | B33: No Change
A34: Interceptor Email Security — Requested Action | B34: No Change
A35: Interceptor Browser Security — Requested Action | B35: No Change
A36: Email Data Protection — Requested Action | B36: No Change
A37: Deployment Change Requested? | B37: On-Prem to Cloud
A39: Legend: Blue cells = editable inputs. Pre-filled with an example renewal for Acme Financial Corp, requesting to add Identity Security and migrate On-Prem to Cloud — deliberately chosen to demonstrate both escalation flags in Renewal_Calculation.
A41: Account Manager
A42: Account Manager Name (free text) | B42: Priya Sharma
A43: Team / Market Segment (free text) | B43: Enterprise — BFSI & Healthcare

Sheet Renewal_Overview
A1: RENEWAL OVERVIEW — Existing Customer (Account Manager View)
A3: Currency | B3: USD
A5: Renewal Snapshot
A6: Customer Name | B6: =Renewal_Input!B3 -> Acme Financial Corp
A7: Account Manager Name | B7: =Renewal_Input!B42 -> Priya Sharma
A8: Team / Market Segment | B8: =Renewal_Input!B43 -> Enterprise — BFSI & Healthcare
A9: Licensed Users | B9: =Renewal_Input!B7 -> 1800
A10: Assigned Size Band | B10: =Renewal_Input!B8 -> Mid
A11: Prior Deployment Type | B11: =Renewal_Input!B6 -> On-Prem
A12: New Deployment Type | B12: =Renewal_Calculation!B36 -> Cloud
A13: Renewal Term | B13: =Renewal_Input!B25 -> 2yr
A14: Platform Tier | B14: =Renewal_Input!B5 -> Data Security Advanced
A16: RECURRING (Renewal ARR)
A17: ="All amounts shown in: "&B3 -> All amounts shown in: USD
A18: Prior Contract Value | B18: =Renewal_Calculation!$B$75 -> 88696.8
A19: Base Renewal Value (post-uplift, before module changes) | B19: =Renewal_Calculation!$B$6*Renewal_Calculation!$B$69 -> 94905.576
A21: Module Changes This Renewal (line items)
A22: MDDR (Managed Detection & Response) | B22: =Renewal_Calculation!$E$15*Renewal_Calculation!$B$69 -> 0
A23: Identity Resolution | B23: =Renewal_Calculation!$E$16*Renewal_Calculation!$B$69 -> 3840
A24: Identity Posture | B24: =Renewal_Calculation!$E$17*Renewal_Calculation!$B$69 -> 0
A25: AI Security (Atlas) | B25: =Renewal_Calculation!$E$18*Renewal_Calculation!$B$69 -> 0
A26: Database Activity Monitoring | B26: =Renewal_Calculation!$E$22*Renewal_Calculation!$B$69 -> 0
A27: Data-Centric UEBA | B27: =Renewal_Calculation!$E$23*Renewal_Calculation!$B$69 -> 0
A28: DLP (Data Loss Prevention) | B28: =Renewal_Calculation!$E$24*Renewal_Calculation!$B$69 -> 0
A29: ITDR | B29: =Renewal_Calculation!$E$25*Renewal_Calculation!$B$69 -> 0
A30: Interceptor Email Security | B30: =Renewal_Calculation!$E$26*Renewal_Calculation!$B$69 -> 0
A31: Interceptor Browser Security | B31: =Renewal_Calculation!$E$27*Renewal_Calculation!$B$69 -> 0
A32: Email Data Protection | B32: =Renewal_Calculation!$E$28*Renewal_Calculation!$B$69 -> 0
A34: Renewal ACV | B34: =Renewal_Calculation!$B$71 -> 117726.69
A35: Growth / (Shrinkage) vs. Prior | B35: =B34-Renewal_Calculation!$B$75 -> 29029.891
A36: Discount % (live input)
A37: Net Renewal ACV | B37: =B34*(1-B36) -> 117726.69
A38: PUPY (Per User Per Year) | B38: =B37/Renewal_Input!$B$7 -> 65.403717
A39: PUPM (Per User Per Month) | B39: =B38/12 -> 5.4503098
A40: Renewal Shrinkage Flag | B40: =Renewal_Calculation!$B$63 -> OK
A42: ONE-TIME (Implementation)
A43: Deployment Change Requested | B43: =Renewal_Calculation!$B$34 -> On-Prem to Cloud
A44: Core Platform (Migration) | B44: =Renewal_Calculation!$B$72 -> 15000
A45: MDDR (Managed Detection & Response) | B45: =Renewal_Calculation!$B$44*Renewal_Calculation!$B$69 -> 0
A46: Identity Resolution | B46: =Renewal_Calculation!$B$45*Renewal_Calculation!$B$69 -> 1600
...

Sheet Renewal_Calculation
A1: RENEWAL CALCULATION — Uplift, Add/Remove, Migration (Pricing Team Only — Hidden/Protected)
A3: Base Renewal Value
A4: Prior Contract Value | B4: =Renewal_Input!B4 -> 88696.8
A5: Renewal Uplift % | B5: =Lookup_Tables!$B$87 -> 0.07
A6: Base Renewal Value | B6: =B4*(1+B5) -> 94905.576
A8: Reference: Current Core Platform Price
A9: Assigned Size Band | B9: =Renewal_Input!B8 -> Mid
A10: Platform Tier | B10: =Renewal_Input!B5 -> Data Security Advanced
A11: Core Platform List Price (reference) | B11: =INDEX(Lookup_Tables!$B$14:$E$15,MATCH($B$10,Lookup_Tables!$A$14:$A$15,0),MATCH($B$9,Lookup_Tables!$B$13:$E$13,0)) -> 48000
A13: Add-On Change Adjustments (% uplift-based)
A14: Add-On | B14: Prior Status | C14: Requested Action | D14: Uplift % | E14: Adjustment
A15: MDDR (Managed Detection & Response) | B15: =Renewal_Input!B12 -> Yes | C15: =Renewal_Input!B26 -> No Change | D15: =Lookup_Tables!$B$21 -> 0.25 | E15: =IF(AND(C15="Add",B15="No"),$B$11*D15,IF(AND(C15="Remove",B15="Yes"),-$B$11*D15,0)) -> 0
A16: Identity Resolution | B16: =Renewal_Input!B13 -> No | C16: =Renewal_Input!B27 -> Add | D16: =Lookup_Tables!$B$22 -> 0.08 | E16: =IF(AND(C16="Add",B16="No"),$B$11*D16,IF(AND(C16="Remove",B16="Yes"),-$B$11*D16,0)) -> 3840
A17: Identity Posture | B17: =Renewal_Input!B14 -> No | C17: =Renewal_Input!B28 -> No Change | D17: =Lookup_Tables!$B$23 -> 0.08 | E17: =IF(AND(C17="Add",B17="No"),$B$11*D17,IF(AND(C17="Remove",B17="Yes"),-$B$11*D17,0)) -> 0
A18: AI Security (Atlas) | B18: =Renewal_Input!B15 -> No | C18: =Renewal_Input!B29 -> No Change | D18: =Lookup_Tables!$B$24 -> 0.1 | E18: =IF(AND(C18="Add",B18="No"),$B$11*D18,IF(AND(C18="Remove",B18="Yes"),-$B$11*D18,0)) -> 0
A20: Additional Modules Change Adjustments (flat price-based)
A21: Module | B21: Prior Status | C21: Requested Action | D21: Unit Price | E21: Adjustment
A22: Database Activity Monitoring | B22: =Renewal_Input!B16 -> No | C22: =Renewal_Input!B30 -> No Change | D22: =INDEX(Lookup_Tables!$B$30:$E$30,MATCH($B$9,Lookup_Tables!$B$29:$E$29,0)) -> 11000 | E22: =IF(AND(C22="Add",B22="No"),D22,IF(AND(C22="Remove",B22="Yes"),-D22,0)) -> 0
A23: Data-Centric UEBA | B23: =Renewal_Input!B17 -> No | C23: =Renewal_Input!B31 -> No Change | D23: =INDEX(Lookup_Tables!$B$31:$E$31,MATCH($B$9,Lookup_Tables!$B$29:$E$29,0)) -> 13000 | E23: =IF(AND(C23="Add",B23="No"),D23,IF(AND(C23="Remove",B23="Yes"),-D23,0)) -> 0
A24: DLP (Data Loss Prevention) | B24: =Renewal_Input!B18 -> No | C24: =Renewal_Input!B32 -> No Change | D24: =INDEX(Lookup_Tables!$B$32:$E$32,MATCH($B$9,Lookup_Tables!$B$29:$E$29,0)) -> 12000 | E24: =IF(AND(C24="Add",B24="No"),D24,IF(AND(C24="Remove",B24="Yes"),-D24,0)) -> 0
A25: ITDR | B25: =Renewal_Input!B19 -> No | C25: =Renewal_Input!B33 -> No Change | D25: =INDEX(Lookup_Tables!$B$33:$E$33,MATCH($B$9,Lookup_Tables!$B$29:$E$29,0)) -> 14000 | E25: =IF(AND(C25="Add",B25="No"),D25,IF(AND(C25="Remove",B25="Yes"),-D25,0)) -> 0
A26: Interceptor Email Security | B26: =Renewal_Input!B20 -> No | C26: =Renewal_Input!B34 -> No Change | D26: =INDEX(Lookup_Tables!$B$34:$E$34,MATCH($B$9,Lookup_Tables!$B$29:$E$29,0)) -> 5500 | E26: =IF(AND(C26="Add",B26="No"),D26,IF(AND(C26="Remove",B26="Yes"),-D26,0)) -> 0
A27: Interceptor Browser Security | B27: =Renewal_Input!B21 -> No | C27: =Renewal_Input!B35 -> No Change | D27: =INDEX(Lookup_Tables!$B$35:$E$35,MATCH($B$9,Lookup_Tables!$B$29:$E$29,0)) -> 3500 | E27: =IF(AND(C27="Add",B27="No"),D27,IF(AND(C27="Remove",B27="Yes"),-D27,0)) -> 0
A28: Email Data Protection | B28: =Renewal_Input!B22 -> No | C28: =Renewal_Input!B36 -> No Change | D28: =INDEX(Lookup_Tables!$B$36:$E$36,MATCH($B$9,Lookup_Tables!$B$29:$E$29,0)) -> 7000 | E28: =IF(AND(C28="Add",B28="No"),D28,IF(AND(C28="Remove",B28="Yes"),-D28,0)) -> 0
A30: Total Add/Remove Adjustment | E30: =E15+E16+E17+E18+E22+E23+E24+E25+E26+E27+E28 -> 3840
A31: Net Renewal ACV (pre-migration) | B31: =B6+E30 -> 98745.576
A33: Deployment Migration
A34: Deployment Change Requested | B34: =Renewal_Input!B37 -> On-Prem to Cloud
A35: Prior Deployment Type | B35: =Renewal_Input!B6 -> On-Prem
A36: New Deployment Type (derived) | B36: =IF(B34="On-Prem to Cloud","Cloud",IF(B34="Cloud to On-Prem","On-Prem",B35)) -> Cloud
A37: Old Deployment Multiplier | B37: =IF(B35="Cloud",Lookup_Tables!$B$44,Lookup_Tables!$B$45) -> 1
A38: New Deployment Multiplier | B38: =IF(B36="Cloud",Lookup_Tables!$B$44,Lookup_Tables!$B$45) -> 1.2
A39: Migration Recurring Adjustment | B39: =IF(B34<>"No",B6*(B38/B37-1),0) -> 18981.115
A40: Migration Implementation Fee (USD) | B40: =IF(B34<>"No",INDEX(Lookup_Tables!$B$54:$E$66,MATCH(IF(B36="Cloud","Core Platform — Cloud","Core Platform — On-Prem"),Lookup_Tables!$A$54:$A$66,0),MATCH($B$9,Lookup_Tables!$B$13:$E$13,0)),0) -> 15000
A42: Newly Added Module Implementation Fees (USD)
A43: Only fires for items transitioning No -> Add this renewal; unchanged/removed items carry no new implementation cost.
A44: MDDR (Managed Detection & Response) Implementation | B44: =IF(AND(Renewal_Input!B26="Add",Renewal_Input!B12="No"),INDEX(Lookup_Tables!$B$56:$E$56,MATCH($B$9,Lookup_Tables!$B$13:$E$13,0)),0) -> 0
A45: Identity Resolution Implementation | B45: =IF(AND(Renewal_Input!B27="Add",Renewal_Input!B13="No"),INDEX(Lookup_Tables!$B$57:$E$57,MATCH($B$9,Lookup_Tables!$B$13:$E$13,0)),0) -> 1600
A46: Identity Posture Implementation | B46: =IF(AND(Renewal_Input!B28="Add",Renewal_Input!B14="No"),INDEX(Lookup_Tables!$B$58:$E$58,MATCH($B$9,Lookup_Tables!$B$13:$E$13,0)),0) -> 0
A47: AI Security (Atlas) Implementation | B47: =IF(AND(Renewal_Input!B29="Add",Renewal_Input!B15="No"),INDEX(Lookup_Tables!$B$59:$E$59,MATCH($B$9,Lookup_Tables!$B$13:$E$13,0)),0) -> 0
...

Sheet Competitive_Benchmark
A1: COMPETITIVE BENCHMARK — Manually Researched, Isolated From Pricing Engine
A3: Competitor pricing is modeled as a positioning multiplier against Varonis' own List ACV for THIS deal, rather than a fixed dollar quote. A fixed quote would go stale the moment modules are added/removed on a deal; a multiplier tied to Varonis' own evolving scope keeps the comparison meaningfully like-for-like as the quote changes. Multipliers are manually researched/estimated (USD basis) — nothing here feeds back into the pricing engine except the single Delta cell (row 18), which flows one-way into Deal_Overview.
A6: Competitor | B6: Positioning Multiplier (vs. Varonis List ACV) | C6: Pricing Model | D6: Notes
A7: Microsoft Purview | B7: 0.7 | C7: Bundled into M365 licensing | D7: Lower multiplier reflects M365 bundling advantage (cheaper attach) but narrower breadth — no equivalent to Interceptor, ITDR, or Email Data Protection as standalone modules
A8: Rubrik | B8: 0.95 | C8: Modular, backup-security adjacent | D8: Comparable modularity; strong in ransomware recovery, weaker on identity/email security breadth
A9: BigID | B9: 0.9 | C9: Modular, discovery/classification-led | D9: Comparable DSPM-first positioning; less mature on MDDR-equivalent managed detection
A10: Netskope | B10: 1.05 | C10: Bundled SSE/SASE suite | D10: Broader network security play; premium multiplier reflects wider platform scope beyond pure data security
A12: [ASSUMPTION] Multipliers are illustrative estimates of relative pricing position, not verified competitor quotes — replace with real researched ratios. Kept in USD regardless of Deal_Overview currency selection, for consistent internal benchmarking. Re-review multipliers whenever Additional Modules are added to the Varonis lineup, since a competitor may or may not have an equivalent capability.
A14: Delta vs. Varonis (This Deal)
A15: Varonis List ACV (this deal, USD, full scope) | B15: =NB_Pricing_Calculation!$B$31 -> 95843.76
A16: Selected Competitor for Comparison | B16: Microsoft Purview
A17: Competitor Equivalent Quote (USD) | B17: =B15*INDEX(Competitive_Benchmark!$B$7:$B$10,MATCH(B16,Competitive_Benchmark!$A$7:$A$10,0)) -> 67090.632
A18: Delta ($) — Varonis minus Competitor | B18: =B15-B17 -> 28753.128
A19: Delta (%) — Varonis vs. Competitor | B19: =IFERROR(B18/B17,"n/a") -> 0.42857143
